2019-06-04 16:08:11,289 ERROR: Exception on /explore [GET] [in /home/fk/py/microblog/venv/lib/python2.7/site-packages/flask/app.py:1761]
Traceback (most recent call last):
  File "/home/fk/py/microblog/venv/lib/python2.7/site-packages/flask/app.py", line 2292, in wsgi_app
    response = self.full_dispatch_request()
  File "/home/fk/py/microblog/venv/lib/python2.7/site-packages/flask/app.py", line 1815, in full_dispatch_request
    rv = self.handle_user_exception(e)
  File "/home/fk/py/microblog/venv/lib/python2.7/site-packages/flask/app.py", line 1718, in handle_user_exception
    reraise(exc_type, exc_value, tb)
  File "/home/fk/py/microblog/venv/lib/python2.7/site-packages/flask/app.py", line 1813, in full_dispatch_request
    rv = self.dispatch_request()
  File "/home/fk/py/microblog/venv/lib/python2.7/site-packages/flask/app.py", line 1799, in dispatch_request
    return self.view_functions[rule.endpoint](**req.view_args)
  File "/home/fk/py/microblog/venv/lib/python2.7/site-packages/flask_login/utils.py", line 261, in decorated_view
    return func(*args, **kwargs)
  File "/home/fk/py/microblog/app/main/routes.py", line 61, in explore
    prev_url=prev_url)
  File "/home/fk/py/microblog/venv/lib/python2.7/site-packages/flask/templating.py", line 135, in render_template
    context, ctx.app)
  File "/home/fk/py/microblog/venv/lib/python2.7/site-packages/flask/templating.py", line 117, in _render
    rv = template.render(context)
  File "/home/fk/py/microblog/venv/lib/python2.7/site-packages/jinja2/environment.py", line 1008, in render
    return self.environment.handle_exception(exc_info, True)
  File "/home/fk/py/microblog/venv/lib/python2.7/site-packages/jinja2/environment.py", line 780, in handle_exception
    reraise(exc_type, exc_value, tb)
  File "/home/fk/py/microblog/app/templates/index.html", line 2, in top-level template code
    {% import 'bootstrap/wtf.html' as wtf %}
  File "/home/fk/py/microblog/app/templates/base.html", line 1, in top-level template code
    {% extends 'bootstrap/base.html' %}
  File "/home/fk/py/microblog/venv/lib/python2.7/site-packages/flask_bootstrap/templates/bootstrap/base.html", line 1, in top-level template code
    {% block doc -%}
  File "/home/fk/py/microblog/venv/lib/python2.7/site-packages/flask_bootstrap/templates/bootstrap/base.html", line 4, in block "doc"
    {%- block html %}
  File "/home/fk/py/microblog/venv/lib/python2.7/site-packages/flask_bootstrap/templates/bootstrap/base.html", line 20, in block "html"
    {% block body -%}
  File "/home/fk/py/microblog/venv/lib/python2.7/site-packages/flask_bootstrap/templates/bootstrap/base.html", line 23, in block "body"
    {% block content -%}
  File "/home/fk/py/microblog/app/templates/base.html", line 48, in block "content"
    {% block app_content %}{% endblock %}
  File "/home/fk/py/microblog/app/templates/index.html", line 11, in block "app_content"
    {% include '_post.html' %}
  File "/home/fk/py/microblog/app/templates/_post.html", line 5, in top-level template code
    <img src="{{ post.author.avatar(70) }}" />
UndefinedError: 'None' has no attribute 'avatar'
2019-06-04 16:25:17,309 INFO: Microblog startup [in /home/fk/py/microblog/app/__init__.py:74]
2019-06-04 16:28:17,729 INFO: Microblog startup [in /home/fk/py/microblog/app/__init__.py:74]
2019-06-07 14:09:57,035 INFO: Microblog startup [in /home/fk/py/microblog/app/__init__.py:74]
2019-06-07 14:55:00,081 INFO: Microblog startup [in /home/fk/py/microblog/app/__init__.py:77]
2019-06-07 15:19:42,613 INFO: Microblog startup [in /home/fk/py/microblog/app/__init__.py:77]
2019-06-07 15:19:57,281 ERROR: Exception on / [GET] [in /home/fk/py/microblog/venv/lib/python2.7/site-packages/flask/app.py:1761]
Traceback (most recent call last):
  File "/home/fk/py/microblog/venv/lib/python2.7/site-packages/flask/app.py", line 2292, in wsgi_app
    response = self.full_dispatch_request()
  File "/home/fk/py/microblog/venv/lib/python2.7/site-packages/flask/app.py", line 1815, in full_dispatch_request
    rv = self.handle_user_exception(e)
  File "/home/fk/py/microblog/venv/lib/python2.7/site-packages/flask/app.py", line 1718, in handle_user_exception
    reraise(exc_type, exc_value, tb)
  File "/home/fk/py/microblog/venv/lib/python2.7/site-packages/flask/app.py", line 1811, in full_dispatch_request
    rv = self.preprocess_request()
  File "/home/fk/py/microblog/venv/lib/python2.7/site-packages/flask/app.py", line 2087, in preprocess_request
    rv = func()
  File "/home/fk/py/microblog/app/main/routes.py", line 19, in before_request
    g.search_form = SearchForm()
NameError: global name 'SearchForm' is not defined
2019-06-07 15:21:03,672 INFO: Microblog startup [in /home/fk/py/microblog/app/__init__.py:77]
2019-06-07 15:21:20,648 ERROR: Exception on /search [GET] [in /home/fk/py/microblog/venv/lib/python2.7/site-packages/flask/app.py:1761]
Traceback (most recent call last):
  File "/home/fk/py/microblog/venv/lib/python2.7/site-packages/flask/app.py", line 2292, in wsgi_app
    response = self.full_dispatch_request()
  File "/home/fk/py/microblog/venv/lib/python2.7/site-packages/flask/app.py", line 1815, in full_dispatch_request
    rv = self.handle_user_exception(e)
  File "/home/fk/py/microblog/venv/lib/python2.7/site-packages/flask/app.py", line 1718, in handle_user_exception
    reraise(exc_type, exc_value, tb)
  File "/home/fk/py/microblog/venv/lib/python2.7/site-packages/flask/app.py", line 1813, in full_dispatch_request
    rv = self.dispatch_request()
  File "/home/fk/py/microblog/venv/lib/python2.7/site-packages/flask/app.py", line 1799, in dispatch_request
    return self.view_functions[rule.endpoint](**req.view_args)
  File "/home/fk/py/microblog/venv/lib/python2.7/site-packages/flask_login/utils.py", line 261, in decorated_view
    return func(*args, **kwargs)
  File "/home/fk/py/microblog/app/main/routes.py", line 143, in search
    current_app.config['POSTS_PER_PAGE'])
  File "/home/fk/py/microblog/app/models.py", line 15, in search
    ids, total = query_index(cls.__tablename__, expression, page, per_page)
  File "/home/fk/py/microblog/app/search.py", line 23, in query_index
    'from': (page - 1) * per_page, 'size': per_page})
  File "/home/fk/py/microblog/venv/lib/python2.7/site-packages/elasticsearch/client/utils.py", line 84, in _wrapped
    return func(*args, params=params, **kwargs)
TypeError: search() got an unexpected keyword argument 'doc_type'
2019-06-07 15:28:47,918 INFO: Microblog startup [in /home/fk/py/microblog/app/__init__.py:77]
2019-06-07 15:29:13,566 ERROR: Exception on /search [GET] [in /home/fk/py/microblog/venv/lib/python2.7/site-packages/flask/app.py:1761]
Traceback (most recent call last):
  File "/home/fk/py/microblog/venv/lib/python2.7/site-packages/flask/app.py", line 2292, in wsgi_app
    response = self.full_dispatch_request()
  File "/home/fk/py/microblog/venv/lib/python2.7/site-packages/flask/app.py", line 1815, in full_dispatch_request
    rv = self.handle_user_exception(e)
  File "/home/fk/py/microblog/venv/lib/python2.7/site-packages/flask/app.py", line 1718, in handle_user_exception
    reraise(exc_type, exc_value, tb)
  File "/home/fk/py/microblog/venv/lib/python2.7/site-packages/flask/app.py", line 1813, in full_dispatch_request
    rv = self.dispatch_request()
  File "/home/fk/py/microblog/venv/lib/python2.7/site-packages/flask/app.py", line 1799, in dispatch_request
    return self.view_functions[rule.endpoint](**req.view_args)
  File "/home/fk/py/microblog/venv/lib/python2.7/site-packages/flask_login/utils.py", line 261, in decorated_view
    return func(*args, **kwargs)
  File "/home/fk/py/microblog/app/main/routes.py", line 143, in search
    current_app.config['POSTS_PER_PAGE'])
  File "/home/fk/py/microblog/app/models.py", line 15, in search
    ids, total = query_index(cls.__tablename__, expression, page, per_page)
  File "/home/fk/py/microblog/app/search.py", line 23, in query_index
    'from': (page - 1) * per_page, 'size': per_page})
  File "/home/fk/py/microblog/venv/lib/python2.7/site-packages/elasticsearch/client/utils.py", line 84, in _wrapped
    return func(*args, params=params, **kwargs)
  File "/home/fk/py/microblog/venv/lib/python2.7/site-packages/elasticsearch/client/__init__.py", line 819, in search
    "GET", _make_path(index, "_search"), params=params, body=body
  File "/home/fk/py/microblog/venv/lib/python2.7/site-packages/elasticsearch/transport.py", line 353, in perform_request
    timeout=timeout,
  File "/home/fk/py/microblog/venv/lib/python2.7/site-packages/elasticsearch/connection/http_urllib3.py", line 251, in perform_request
    self._raise_error(response.status, raw_data)
  File "/home/fk/py/microblog/venv/lib/python2.7/site-packages/elasticsearch/connection/base.py", line 178, in _raise_error
    status_code, error_message, additional_info
NotFoundError: NotFoundError(404, u'index_not_found_exception', u'no such index [post]', post, index_or_alias)
